<?xml version="1.0" ?>
<!-- =================================================================================== -->
<!-- |    This document was autogenerated by xacro from robot_waiter.xacro             | -->
<!-- |    EDITING THIS FILE BY HAND IS NOT RECOMMENDED                                 | -->
<!-- =================================================================================== -->
<!-- robot_waiter.xacro: robot cameriere con ruote sferiche sotto la base -->
<robot name="robot_waiter">
  <material name="body_mat">
    <color rgba="0.8 0.8 0.8 1.0"/>
  </material>
  <material name="wheel_mat">
    <color rgba="0.1 0.1 0.1 1.0"/>
  </material>
  <material name="tray_mat">
    <color rgba="0.9 0.7 0.2 1.0"/>
  </material>
  <!-- Base cilindrica -->
  <link name="base_link">
    <visual>
      <origin rpy="0 0 0" xyz="0 0 0.14"/>
      <geometry>
        <cylinder length="0.1" radius="0.25"/>
      </geometry>
      <material name="body_mat"/>
    </visual>
    <collision>
      <origin rpy="0 0 0" xyz="0 0 0.07"/>
      <geometry>
        <cylinder length="0.1" radius="0.25"/>
      </geometry>
    </collision>
    <inertial>
      <mass value="5.0"/>
      <inertia ixx="0.1" ixy="0.0" ixz="0.0" iyy="0.1" iyz="0.0" izz="0.1"/>
      <origin xyz="0 0 0.07"/>
    </inertial>
  </link>
  <!-- Ruote sferiche (sfere) -->
  <!-- Posizione a terra (origine centro sfera a z=wheel_radius) -->
  <!-- Ruota anteriore sinistra -->
  <link name="wheel_fl_link">
    <visual>
      <origin rpy="0 0 0" xyz="0.18 0.18 0.07"/>
      <geometry>
        <sphere radius="0.07"/>
      </geometry>
      <material name="wheel_mat"/>
    </visual>
    <collision>
      <origin rpy="0 0 0" xyz="0.18 0.18 0.07"/>
      <geometry>
        <sphere radius="0.07"/>
      </geometry>
    </collision>
    <inertial>
      <mass value="1.0"/>
      <inertia ixx="0.01" ixy="0.0" ixz="0.0" iyy="0.01" iyz="0.0" izz="0.01"/>
    </inertial>
  </link>
  <joint name="base_to_wheel_fl" type="continuous">
    <parent link="base_link"/>
    <child link="wheel_fl_link"/>
    <origin rpy="0 0 0" xyz="0.18 0.18 0.0"/>
    <axis xyz="0 1 0"/>
  </joint>
  <!-- Ruota anteriore destra -->
  <link name="wheel_fr_link">
    <visual>
      <origin rpy="0 0 0" xyz="0.18 -0.18 0.07"/>
      <geometry>
        <sphere radius="0.07"/>
      </geometry>
      <material name="wheel_mat"/>
    </visual>
    <collision>
      <origin rpy="0 0 0" xyz="0.18 -0.18 0.07"/>
      <geometry>
        <sphere radius="0.07"/>
      </geometry>
    </collision>
    <inertial>
      <mass value="1.0"/>
      <inertia ixx="0.01" ixy="0.0" ixz="0.0" iyy="0.01" iyz="0.0" izz="0.01"/>
    </inertial>
  </link>
  <joint name="base_to_wheel_fr" type="continuous">
    <parent link="base_link"/>
    <child link="wheel_fr_link"/>
    <origin rpy="0 0 0" xyz="0.18 -0.18 0.0"/>
    <axis xyz="0 1 0"/>
  </joint>
  <!-- Ruota posteriore sinistra -->
  <link name="wheel_rl_link">
    <visual>
      <origin rpy="0 0 0" xyz="-0.18 0.18 0.07"/>
      <geometry>
        <sphere radius="0.07"/>
      </geometry>
      <material name="wheel_mat"/>
    </visual>
    <collision>
      <origin rpy="0 0 0" xyz="-0.18 0.18 0.07"/>
      <geometry>
        <sphere radius="0.07"/>
      </geometry>
    </collision>
    <inertial>
      <mass value="1.0"/>
      <inertia ixx="0.01" ixy="0.0" ixz="0.0" iyy="0.01" iyz="0.0" izz="0.01"/>
    </inertial>
  </link>
  <joint name="base_to_wheel_rl" type="continuous">
    <parent link="base_link"/>
    <child link="wheel_rl_link"/>
    <origin rpy="0 0 0" xyz="-0.18 0.18 0.0"/>
    <axis xyz="0 1 0"/>
  </joint>
  <!-- Ruota posteriore destra -->
  <link name="wheel_rr_link">
    <visual>
      <origin rpy="0 0 0" xyz="-0.18 -0.18 0.07"/>
      <geometry>
        <sphere radius="0.07"/>
      </geometry>
      <material name="wheel_mat"/>
    </visual>
    <collision>
      <origin rpy="0 0 0" xyz="-0.18 -0.18 0.07"/>
      <geometry>
        <sphere radius="0.07"/>
      </geometry>
    </collision>
    <inertial>
      <mass value="1.0"/>
      <inertia ixx="0.01" ixy="0.0" ixz="0.0" iyy="0.01" iyz="0.0" izz="0.01"/>
    </inertial>
  </link>
  <joint name="base_to_wheel_rr" type="continuous">
    <parent link="base_link"/>
    <child link="wheel_rr_link"/>
    <origin rpy="0 0 0" xyz="-0.18 -0.18 0.0"/>
    <axis xyz="0 1 0"/>
  </joint>
  <!-- Vassoio -->
  <link name="tray_link">
    <visual>
      <origin rpy="0 0 0" xyz="0 0 0.2"/>
      <geometry>
        <box size="0.5 0.3 0.02"/>
      </geometry>
      <material name="tray_mat"/>
    </visual>
    <collision>
      <origin rpy="0 0 0" xyz="0 0 0.2"/>
      <geometry>
        <box size="0.5 0.3 0.02"/>
      </geometry>
    </collision>
    <inertial>
      <mass value="2.0"/>
      <inertia ixx="0.02" ixy="0.0" ixz="0.0" iyy="0.02" iyz="0.0" izz="0.02"/>
    </inertial>
  </link>
  <joint name="base_to_tray" type="fixed">
    <parent link="base_link"/>
    <child link="tray_link"/>
    <origin rpy="0 0 0" xyz="0 0 0"/>
  </joint>
  <!-- Gazebo static -->
  <gazebo reference="base_link">
    <static>true</static>
  </gazebo>
</robot>
